Workbook

Sheet 明细
A1: 序号 | B1: 报表月份 | C1: 供应单位 | D1: 供应商全称 | E1: 报表月份供应商 | F1: 运输单位 | G1: 车数 | H1: 重量 | I1: 矿发量 | J1: 发热量 | K1: 矿发热量 | L1: 运费单价 | M1: 运费 | N1: 到厂价格 | O1: 矿发价格
A2: 1 | B2: 2024-01 | C2: 大同煤矿集团北辛窑煤业有限公司（1-1火车） | D2: 大同煤矿集团北辛窑煤业有限公司 | E2: 2024-01-大同煤矿集团北辛窑煤业有限公司 | F2: 晋能快成物流科技有限公司 | G2: 1403 | H2: 26101.84 | J2: 3501 | L2: =VLOOKUP(D2,运费!B:C,2,0) -> 147.1 | M2: =H2*L2 -> 3839580.7 | N2: {=(_xlfn.IFS(J2>=4300,570/550*J2,J2>=3800,0.0806*J2,J2>=3300,0.0706*J2,J2>=2500,0.0676*J2,TRUE,0.02*J2)+10)*H2} -> 6712625.9
A3: 2 | B3: 2024-01 | C3: 大同煤矿集团有限公司程家沟煤矿（1-1火车宝特） | D3: 大同煤矿集团有限公司程家沟煤矿 | E3: 2024-01-大同煤矿集团有限公司程家沟煤矿 | F3: 晋能快成物流科技有限公司 | G3: 500 | H3: 14377.61 | J3: 3311 | L3: =VLOOKUP(D3,运费!B:C,2,0) -> 192.75 | M3: =H3*L3 -> 2771284.3 | N3: {=(_xlfn.IFS(J3>=4300,570/550*J3,J3>=3800,0.0806*J3,J3>=3300,0.0706*J3,J3>=2500,0.0676*J3,TRUE,0.02*J3)+10)*H3} -> 3504637.3
A4: 3 | B4: 2024-01 | C4: 河南农投供应链管理有限公司（1-1） | D4: 河南农投供应链管理有限公司 | E4: 2024-01-河南农投供应链管理有限公司 | F4: 晋能快成物流科技有限公司 | G4: 179 | H4: 3339.04 | J4: 4481 | L4: =VLOOKUP(D4,运费!B:C,2,0) -> 21.8 | M4: =H4*L4 -> 72791.072 | N4: {=(_xlfn.IFS(J4>=4300,570/550*J4,J4>=3800,0.0806*J4,J4>=3300,0.0706*J4,J4>=2500,0.0676*J4,TRUE,0.02*J4)+10)*H4} -> 15539710
A5: 4 | B5: 2024-01 | C5: 河南农投供应链管理有限公司（12-2增量） | D5: 河南农投供应链管理有限公司 | E5: 2024-01-河南农投供应链管理有限公司 | F5: 晋能快成物流科技有限公司 | G5: 262 | H5: 4852.58 | J5: 4481 | L5: =VLOOKUP(D5,运费!B:C,2,0) -> 21.8 | M5: =H5*L5 -> 105786.24 | N5: {=(_xlfn.IFS(J5>=4300,570/550*J5,J5>=3800,0.0806*J5,J5>=3300,0.0706*J5,J5>=2500,0.0676*J5,TRUE,0.02*J5)+10)*H5} -> 22583643
A6: 5 | B6: 2024-01 | C6: 洪洞阳光能源有限公司（12-1） | D6: 洪洞阳光能源有限公司 | E6: 2024-01-洪洞阳光能源有限公司 | F6: 晋能快成物流科技有限公司 | G6: 235 | H6: 4284.12 | J6: 3960 | L6: =VLOOKUP(D6,运费!B:C,2,0) -> 10.355 | M6: =H6*L6 -> 44362.063 | N6: {=(_xlfn.IFS(J6>=4300,570/550*J6,J6>=3800,0.0806*J6,J6>=3300,0.0706*J6,J6>=2500,0.0676*J6,TRUE,0.02*J6)+10)*H6} -> 1410229.5
A7: 6 | B7: 2024-01 | C7: 侯马鼎坤源能源有限公司（1-1） | D7: 侯马鼎坤源能源有限公司 | E7: 2024-01-侯马鼎坤源能源有限公司 | F7: 晋能快成物流科技有限公司 | G7: 109 | H7: 3296 | J7: 4176 | L7: =VLOOKUP(D7,运费!B:C,2,0) -> 33.79 | M7: =H7*L7 -> 111371.84 | N7: {=(_xlfn.IFS(J7>=4300,570/550*J7,J7>=3800,0.0806*J7,J7>=3300,0.0706*J7,J7>=2500,0.0676*J7,TRUE,0.02*J7)+10)*H7} -> 1142346.1
A8: 7 | B8: 2024-01 | C8: 晋能控股集团盛泰煤业有限公司（1-1） | D8: 晋能控股集团盛泰煤业有限公司 | E8: 2024-01-晋能控股集团盛泰煤业有限公司 | F8: 晋能快成物流科技有限公司 | G8: 612 | H8: 19855.3 | J8: 4288 | L8: =VLOOKUP(D8,运费!B:C,2,0) -> 104.5 | M8: =H8*L8 -> 2074878.8 | N8: {=(_xlfn.IFS(J8>=4300,570/550*J8,J8>=3800,0.0806*J8,J8>=3300,0.0706*J8,J8>=2500,0.0676*J8,TRUE,0.02*J8)+10)*H8} -> 7060798.8
A9: 8 | B9: 2024-01 | C9: 晋能控股煤业集团沁水胡底煤业有限公司（1-1） | D9: 晋能控股煤业集团沁水胡底煤业有限公司 | E9: 2024-01-晋能控股煤业集团沁水胡底煤业有限公司 | F9: 晋能快成物流科技有限公司 | G9: 182 | H9: 5754 | J9: 4511 | L9: =VLOOKUP(D9,运费!B:C,2,0) -> 78 | M9: =H9*L9 -> 448812 | N9: {=(_xlfn.IFS(J9>=4300,570/550*J9,J9>=3800,0.0806*J9,J9>=3300,0.0706*J9,J9>=2500,0.0676*J9,TRUE,0.02*J9)+10)*H9} -> 26957699
A10: 9 | B10: 2024-01 | C10: 晋能控股煤业集团翼城华泓煤业有限公司（1-1） | D10: 晋能控股煤业集团翼城华泓煤业有限公司 | E10: 2024-01-晋能控股煤业集团翼城华泓煤业有限公司 | F10: 晋能快成物流科技有限公司 | G10: 879 | H10: 28078.13 | J10: 4388 | L10: =VLOOKUP(D10,运费!B:C,2,0) -> 58 | M10: =H10*L10 -> 1628531.5 | N10: {=(_xlfn.IFS(J10>=4300,570/550*J10,J10>=3800,0.0806*J10,J10>=3300,0.0706*J10,J10>=2500,0.0676*J10,TRUE,0.02*J10)+10)*H10} -> 1.2796786e+08
A11: 10 | B11: 2024-01 | C11: 临汾市侯马经济开发区鑫鑫商贸有限公司（1-1） | D11: 临汾市侯马经济开发区鑫鑫商贸有限公司 | E11: 2024-01-临汾市侯马经济开发区鑫鑫商贸有限公司 | F11: 晋能快成物流科技有限公司 | G11: 325 | H11: 5873.36 | J11: 4448 | L11: =VLOOKUP(D11,运费!B:C,2,0) -> 10.355 | M11: =H11*L11 -> 60818.643 | N11: {=(_xlfn.IFS(J11>=4300,570/550*J11,J11>=3800,0.0806*J11,J11>=3300,0.0706*J11,J11>=2500,0.0676*J11,TRUE,0.02*J11)+10)*H11} -> 27133428
A12: 11 | B12: 2024-01 | C12: 临汾市侯马经济开发区鑫鑫商贸有限公司（12-1） | D12: 临汾市侯马经济开发区鑫鑫商贸有限公司 | E12: 2024-01-临汾市侯马经济开发区鑫鑫商贸有限公司 | F12: 晋能快成物流科技有限公司 | G12: 118 | H12: 2144.96 | J12: 4448 | L12: =VLOOKUP(D12,运费!B:C,2,0) -> 10.355 | M12: =H12*L12 -> 22211.061 | N12: {=(_xlfn.IFS(J12>=4300,570/550*J12,J12>=3800,0.0806*J12,J12>=3300,0.0706*J12,J12>=2500,0.0676*J12,TRUE,0.02*J12)+10)*H12} -> 9909169.2
A13: 12 | B13: 2024-01 | C13: 山西芳瑞芳菲商贸有限公司(12-2增量) | D13: 山西芳瑞芳菲商贸有限公司 | E13: 2024-01-山西芳瑞芳菲商贸有限公司 | F13: 晋能快成物流科技有限公司 | G13: 132 | H13: 2411.82 | J13: 4032 | L13: =VLOOKUP(D13,运费!B:C,2,0) -> 10.355 | M13: =H13*L13 -> 24974.396 | N13: {=(_xlfn.IFS(J13>=4300,570/550*J13,J13>=3800,0.0806*J13,J13>=3300,0.0706*J13,J13>=2500,0.0676*J13,TRUE,0.02*J13)+10)*H13} -> 807909.53
... A42: 8 | B42: 2024-02 | C42: 山西汾河焦煤股份有限公司三交河煤矿（2-1） | D42: 山西汾河焦煤股份有限公司三交河煤矿 | E42: 2024-02-山西汾河焦煤股份有限公司三交河煤矿 | F42: 山西焦煤物流有限责任公司 | G42: 237 | H42: 7537.78 | J42: 4102 | L42: =VLOOKUP(D42,运费!B:C,2,0) -> 117 | M42: =H42*L42 -> 881920.26 | N42: {=(_xlfn.IFS(J42>=4300,570/550*J42,J42>=3800,0.0806*J42,J42>=3300,0.0706*J42,J42>=2500,0.0676*J42,TRUE,0.02*J42)+10)*H42} -> 2567527.7
A43: 9 | B43: 2024-02 | C43: 山西焦煤汾西矿业昊锦塬煤业(2-1) | D43: 山西焦煤汾西矿业昊锦塬煤业 | E43: 2024-02-山西焦煤汾西矿业昊锦塬煤业 | F43: 山西焦煤物流有限责任公司 | G43: 14 | H43: 441.28 | J43: #N/A | L43: =VLOOKUP(D43,运费!B:C,2,0) -> 81 | M43: =H43*L43 -> 35743.68 | N43: {=(_xlfn.IFS(J43>=4300,570/550*J43,J43>=3800,0.0806*J43,J43>=3300,0.0706*J43,J43>=2500,0.0676*J43,TRUE,0.02*J43)+10)*H43} -> #N/A
A44: 10 | B44: 2024-02 | C44: 山西焦煤集团辛置矿（2-1） | D44: 山西焦煤集团辛置矿 | E44: 2024-02-山西焦煤集团辛置矿 | F44: 山西焦煤物流有限责任公司 | G44: 6 | H44: 193.4 | J44: 4146 | L44: =VLOOKUP(D44,运费!B:C,2,0) -> 79 | M44: =H44*L44 -> 15278.6 | N44: {=(_xlfn.IFS(J44>=4300,570/550*J44,J44>=3800,0.0806*J44,J44>=3300,0.0706*J44,J44>=2500,0.0676*J44,TRUE,0.02*J44)+10)*H44} -> 66562.014
A45: 11 | B45: 2024-02 | C45: 山西骏盛通能源有限公司（1-1） | D45: 山西骏盛通能源有限公司 | E45: 2024-02-山西骏盛通能源有限公司 | F45: 晋能快成物流科技有限公司 | G45: 376 | H45: 6697.86 | J45: 4105 | L45: =VLOOKUP(D45,运费!B:C,2,0) -> 10.355 | M45: =H45*L45 -> 69356.34 | N45: {=(_xlfn.IFS(J45>=4300,570/550*J45,J45>=3800,0.0806*J45,J45>=3300,0.0706*J45,J45>=2500,0.0676*J45,TRUE,0.02*J45)+10)*H45} -> 2283052.7
A46: 12 | B46: 2024-02 | C46: 山西煤炭运销集团盖州煤业有限公司（2-1） | D46: 山西煤炭运销集团盖州煤业有限公司 | E46: 2024-02-山西煤炭运销集团盖州煤业有限公司 | F46: 晋能快成物流科技有限公司 | G46: 77 | H46: 2505.84 | J46: 3959 | L46: =VLOOKUP(D46,运费!B:C,2,0) -> 101.5 | M46: =H46*L46 -> 254342.76 | N46: {=(_xlfn.IFS(J46>=4300,570/550*J46,J46>=3800,0.0806*J46,J46>=3300,0.0706*J46,J46>=2500,0.0676*J46,TRUE,0.02*J46)+10)*H46} -> 824660.42
A47: 13 | B47: 2024-02 | C47: 山西煤炭运销集团神农煤业有限公司（2-1） | D47: 山西煤炭运销集团神农煤业有限公司 | E47: 2024-02-山西煤炭运销集团神农煤业有限公司 | F47: 晋能快成物流科技有限公司 | G47: 13 | H47: 421.96 | J47: #N/A | L47: =VLOOKUP(D47,运费!B:C,2,0) -> 105 | M47: =H47*L47 -> 44305.8 | N47: {=(_xlfn.IFS(J47>=4300,570/550*J47,J47>=3800,0.0806*J47,J47>=3300,0.0706*J47,J47>=2500,0.0676*J47,TRUE,0.02*J47)+10)*H47} -> #N/A
A48: 14 | B48: 2024-02 | C48: 山西煤炭运销集团四明山煤业有限公司（2-1） | D48: 山西煤炭运销集团四明山煤业有限公司 | E48: 2024-02-山西煤炭运销集团四明山煤业有限公司 | F48: 晋能快成物流科技有限公司 | G48: 91 | H48: 2963.04 | J48: 4139 | L48: =VLOOKUP(D48,运费!B:C,2,0) -> 104.5 | M48: =H48*L48 -> 309637.68 | N48: {=(_xlfn.IFS(J48>=4300,570/550*J48,J48>=3800,0.0806*J48,J48>=3300,0.0706*J48,J48>=2500,0.0676*J48,TRUE,0.02*J48)+10)*H48} -> 1018110.6
A49: 15 | B49: 2024-02 | C49: 山西统配煤炭物流有限公司（1-1） | D49: 山西统配煤炭物流有限公司 | E49: 2024-02-山西统配煤炭物流有限公司 | F49: 晋能快成物流科技有限公司 | G49: 292 | H49: 5396.88 | J49: 4283 | L49: =VLOOKUP(D49,运费!B:C,2,0) -> 21.8 | M49: =H49*L49 -> 117651.98 | N49: {=(_xlfn.IFS(J49>=4300,570/550*J49,J49>=3800,0.0806*J49,J49>=3300,0.0706*J49,J49>=2500,0.0676*J49,TRUE,0.02*J49)+10)*H49} -> 1917024.7
A50: 16 | B50: 2024-02 | C50: 山西鑫健商贸有限公司（1-1） | D50: 山西鑫健商贸有限公司 | E50: 2024-02-山西鑫健商贸有限公司 | F50: 晋能快成物流科技有限公司 | G50: 900 | H50: 16706.1 | J50: 4153 | L50: =VLOOKUP(D50,运费!B:C,2,0) -> 21.8 | M50: =H50*L50 -> 364192.98 | N50: {=(_xlfn.IFS(J50>=4300,570/550*J50,J50>=3800,0.0806*J50,J50>=3300,0.0706*J50,J50>=2500,0.0676*J50,TRUE,0.02*J50)+10)*H50} -> 5759123.9
A51: 17 | B51: 2024-02 | C51: 太原煤气化股份有限公司炉峪口煤矿（1-1宝特） | D51: 太原煤气化股份有限公司炉峪口煤矿 | E51: 2024-02-太原煤气化股份有限公司炉峪口煤矿 | F51: 晋能快成物流科技有限公司 | G51: 124 | H51: 3591.06 | J51: 3064 | L51: =VLOOKUP(D51,运费!B:C,2,0) -> 116.8 | M51: =H51*L51 -> 419435.81 | N51: {=(_xlfn.IFS(J51>=4300,570/550*J51,J51>=3800,0.0806*J51,J51>=3300,0.0706*J51,J51>=2500,0.0676*J51,TRUE,0.02*J51)+10)*H51} -> 779713.93
A52: 18 | B52: 2024-02 | C52: 太原煤气化股份有限公司炉峪口煤矿（2-1宝特） | D52: 太原煤气化股份有限公司炉峪口煤矿 | E52: 2024-02-太原煤气化股份有限公司炉峪口煤矿 | F52: 晋能快成物流科技有限公司 | G52: 169 | H52: 3520.84 | J52: 3064 | L52: =VLOOKUP(D52,运费!B:C,2,0) -> 116.8 | M52: =H52*L52 -> 411234.11 | N52: {=(_xlfn.IFS(J52>=4300,570/550*J52,J52>=3800,0.0806*J52,J52>=3300,0.0706*J52,J52>=2500,0.0676*J52,TRUE,0.02*J52)+10)*H52} -> 764467.31
A53: 19 | B53: 2024-02 | C53: 太原煤气化龙泉能源（1-1火车） | D53: 太原煤气化龙泉能源 | E53: 2024-02-太原煤气化龙泉能源 | F53: 晋能快成物流科技有限公司 | G53: 380 | H53: 6978.76 | J53: 4863 | L53: =VLOOKUP(D53,运费!B:C,2,0) -> 108.51 | M53: =H53*L53 -> 757265.25 | N53: {=(_xlfn.IFS(J53>=4300,570/550*J53,J53>=3800,0.0806*J53,J53>=3300,0.0706*J53,J53>=2500,0.0676*J53,TRUE,0.02*J53)+10)*H53} -> 35241596
A54: 20 | B54: 2024-02 | C54: 太原煤气化龙泉能源（2-1火车） | D54: 太原煤气化龙泉能源 | E54: 2024-02-太原煤气化龙泉能源 | F54: 晋能快成物流科技有限公司 | G54: 745 | H54: 13746.38 | J54: 4863 | L54: =VLOOKUP(D54,运费!B:C,2,0) -> 108.51 | M54: =H54*L54 -> 1491619.7 | N54: {=(_xlfn.IFS(J54>=4300,570/550*J54,J54>=3800,0.0806*J54,J54>=3300,0.0706*J54,J54>=2500,0.0676*J54,TRUE,0.02*J54)+10)*H54} -> 69416970
A55: 21 | B55: 2024-02 | C55: 襄汾县浩群煤业有限公司（1-1） | D55: 襄汾县浩群煤业有限公司 | E55: 2024-02-襄汾县浩群煤业有限公司 | F55: 晋能快成物流科技有限公司 | G55: 32 | H55: 723.02 | J55: 4374 | L55: =VLOOKUP(D55,运费!B:C,2,0) -> 33.79 | M55: =H55*L55 -> 24430.846 | N55: {=(_xlfn.IFS(J55>=4300,570/550*J55,J55>=3800,0.0806*J55,J55>=3300,0.0706*J55,J55>=2500,0.0676*J55,TRUE,0.02*J55)+10)*H55} -> 3284719.3
A56: 22 | B56: 2024-02 | C56: 阳泉煤业集团翼城山凹煤业有限公司（2-1） | D56: 阳泉煤业集团翼城山凹煤业有限公司 | E56: 2024-02-阳泉煤业集团翼城山凹煤业有限公司 | F56: 晋能快成物流科技有限公司 | G56: 92 | H56: 2937.34 | J56: 4579 | L56: =VLOOKUP(D56,运费!B:C,2,0) -> 60.5 | M56: =H56*L56 -> 177709.07 | N56: {=(_xlfn.IFS(J56>=4300,570/550*J56,J56>=3800,0.0806*J56,J56>=3300,0.0706*J56,J56>=2500,0.0676*J56,TRUE,0.02*J56)+10)*H56} -> 13968547
A57: 1 | B57: 2024-03 | C57: 大同煤矿集团北辛窑煤业有限公司（2-1火车） | D57: 大同煤矿集团北辛窑煤业有限公司 | E57: 2024-03-大同煤矿集团北辛窑煤业有限公司 | F57: 晋能快成物流科技有限公司 | G57: 1086 | H57: 20164.9 | J57: 3409 | L57: =VLOOKUP(D57,运费!B:C,2,0) -> 147.1 | M57: =H57*L57 -> 2966256.8 | N57: {=(_xlfn.IFS(J57>=4300,570/550*J57,J57>=3800,0.0806*J57,J57>=3300,0.0706*J57,J57>=2500,0.0676*J57,TRUE,0.02*J57)+10)*H57} -> 5054844.4
A58: 2 | B58: 2024-03 | C58: 大同煤矿集团北辛窑煤业有限公司（3-1火车） | D58: 大同煤矿集团北辛窑煤业有限公司 | E58: 2024-03-大同煤矿集团北辛窑煤业有限公司 | F58: 晋能快成物流科技有限公司 | G58: 1393 | H58: 26168.38 | J58: 3409 | L58: =VLOOKUP(D58,运费!B:C,2,0) -> 147.1 | M58: =H58*L58 -> 3849368.7 | N58: {=(_xlfn.IFS(J58>=4300,570/550*J58,J58>=3800,0.0806*J58,J58>=3300,0.0706*J58,J58>=2500,0.0676*J58,TRUE,0.02*J58)+10)*H58} -> 6559769.1
A59: 3 | B59: 2024-03 | C59: 晋能控股集团盛泰煤业有限公司（2-1） | D59: 晋能控股集团盛泰煤业有限公司 | E59: 2024-03-晋能控股集团盛泰煤业有限公司 | F59: 晋能快成物流科技有限公司 | G59: 16 | H59: 517.74 | J59: 3944 | L59: =VLOOKUP(D59,运费!B:C,2,0) -> 104.5 | M59: =H59*L59 -> 54103.83 | N59: {=(_xlfn.IFS(J59>=4300,570/550*J59,J59>=3800,0.0806*J59,J59>=3300,0.0706*J59,J59>=2500,0.0676*J59,TRUE,0.02*J59)+10)*H59} -> 169759.9
... A78: 2 | B78: 2024-04 | C78: 晋能控股集团盛泰煤业有限公司（4-1） | D78: 晋能控股集团盛泰煤业有限公司 | E78: 2024-04-晋能控股集团盛泰煤业有限公司 | F78: 晋能快成物流科技有限公司 | G78: 179 | H78: 5858.72 | J78: 5138 | L78: =VLOOKUP(D78,运费!B:C,2,0) -> 104.5 | M78: =H78*L78 -> 612236.24 | N78: {=(_xlfn.IFS(J78>=4300,570/550*J78,J78>=3800,0.0806*J78,J78>=3300,0.0706*J78,J78>=2500,0.0676*J78,TRUE,0.02*J78)+10)*H78} -> 31255313
A79: 3 | B79: 2024-04 | C79: 晋能控股煤业集团沁水胡底煤业有限公司（4-1） | D79: 晋能控股煤业集团沁水胡底煤业有限公司 | E79: 2024-04-晋能控股煤业集团沁水胡底煤业有限公司 | F79: 晋能快成物流科技有限公司 | G79: 46 | H79: 1437.8 | J79: #N/A | L79: =VLOOKUP(D79,运费!B:C,2,0) -> 78 | M79: =H79*L79 -> 112148.4 | N79: {=(_xlfn.IFS(J79>=4300,570/550*J79,J79>=3800,0.0806*J79,J79>=3300,0.0706*J79,J79>=2500,0.0676*J79,TRUE,0.02*J79)+10)*H79} -> #N/A
A80: 4 | B80: 2024-04 | C80: 晋能控股煤业集团翼城华泓煤业有限公司（4-1） | D80: 晋能控股煤业集团翼城华泓煤业有限公司 | E80: 2024-04-晋能控股煤业集团翼城华泓煤业有限公司 | F80: 晋能快成物流科技有限公司 | G80: 258 | H80: 8264.73 | J80: 3956 | L80: =VLOOKUP(D80,运费!B:C,2,0) -> 58 | M80: =H80*L80 -> 479354.34 | N80: {=(_xlfn.IFS(J80>=4300,570/550*J80,J80>=3800,0.0806*J80,J80>=3300,0.0706*J80,J80>=2500,0.0676*J80,TRUE,0.02*J80)+10)*H80} -> 2717886.2
A81: 5 | B81: 2024-04 | C81: 山西汾河焦煤股份有限公司三交河煤矿（3-1） | D81: 山西汾河焦煤股份有限公司三交河煤矿 | E81: 2024-04-山西汾河焦煤股份有限公司三交河煤矿 | F81: 山西焦煤物流有限责任公司 | G81: 16 | H81: 508.56 | J81: 4368 | L81: =VLOOKUP(D81,运费!B:C,2,0) -> 117 | M81: =H81*L81 -> 59501.52 | N81: {=(_xlfn.IFS(J81>=4300,570/550*J81,J81>=3800,0.0806*J81,J81>=3300,0.0706*J81,J81>=2500,0.0676*J81,TRUE,0.02*J81)+10)*H81} -> 2307253.5
A82: 6 | B82: 2024-04 | C82: 山西汾河焦煤股份有限公司三交河煤矿（4-1） | D82: 山西汾河焦煤股份有限公司三交河煤矿 | E82: 2024-04-山西汾河焦煤股份有限公司三交河煤矿 | F82: 山西焦煤物流有限责任公司 | G82: 310 | H82: 9911.14 | J82: 4368 | L82: =VLOOKUP(D82,运费!B:C,2,0) -> 117 | M82: =H82*L82 -> 1159603.4 | N82: {=(_xlfn.IFS(J82>=4300,570/550*J82,J82>=3800,0.0806*J82,J82>=3300,0.0706*J82,J82>=2500,0.0676*J82,TRUE,0.02*J82)+10)*H82} -> 44965220
A83: 7 | B83: 2024-04 | C83: 山西焦煤汾西矿业昊锦塬煤业(4-1) | D83: 山西焦煤汾西矿业昊锦塬煤业 | E83: 2024-04-山西焦煤汾西矿业昊锦塬煤业 | F83: 山西焦煤物流有限责任公司 | G83: 10 | H83: 309.64 | J83: 3399 | L83: =VLOOKUP(D83,运费!B:C,2,0) -> 81 | M83: =H83*L83 -> 25080.84 | N83: {=(_xlfn.IFS(J83>=4300,570/550*J83,J83>=3800,0.0806*J83,J83>=3300,0.0706*J83,J83>=2500,0.0676*J83,TRUE,0.02*J83)+10)*H83} -> 77400.525
A84: 8 | B84: 2024-04 | C84: 山西焦煤霍州煤电雪坪煤业有限公司（4-1） | D84: 山西焦煤霍州煤电雪坪煤业有限公司 | E84: 2024-04-山西焦煤霍州煤电雪坪煤业有限公司 | F84: 山西焦煤物流有限责任公司 | G84: 44 | H84: 1341.06 | J84: 2974 | L84: =VLOOKUP(D84,运费!B:C,2,0) -> 70 | M84: =H84*L84 -> 93874.2 | N84: {=(_xlfn.IFS(J84>=4300,570/550*J84,J84>=3800,0.0806*J84,J84>=3300,0.0706*J84,J84>=2500,0.0676*J84,TRUE,0.02*J84)+10)*H84} -> 283020.52
A85: 9 | B85: 2024-04 | C85: 山西焦煤集团辛置矿（4-1） | D85: 山西焦煤集团辛置矿 | E85: 2024-04-山西焦煤集团辛置矿 | F85: 山西焦煤物流有限责任公司 | G85: 92 | H85: 2983.36 | J85: 4012 | L85: =VLOOKUP(D85,运费!B:C,2,0) -> 79 | M85: =H85*L85 -> 235685.44 | N85: {=(_xlfn.IFS(J85>=4300,570/550*J85,J85>=3800,0.0806*J85,J85>=3300,0.0706*J85,J85>=2500,0.0676*J85,TRUE,0.02*J85)+10)*H85} -> 994554.37
A86: 10 | B86: 2024-04 | C86: 山西晋煤集团晋圣亿欣煤业有限公司（3-1） | D86: 山西晋煤集团晋圣亿欣煤业有限公司 | E86: 2024-04-山西晋煤集团晋圣亿欣煤业有限公司 | F86: 晋能快成物流科技有限公司 | G86: 44 | H86: 1402.62 | J86: 3765 | L86: =VLOOKUP(D86,运费!B:C,2,0) -> 67 | M86: =H86*L86 -> 93975.54 | N86: {=(_xlfn.IFS(J86>=4300,570/550*J86,J86>=3800,0.0806*J86,J86>=3300,0.0706*J86,J86>=2500,0.0676*J86,TRUE,0.02*J86)+10)*H86} -> 386855.22
...

Sheet 明细 (2)
A1: 序号 | B1: 报表月份 | C1: 供应单位 | D1: 供应商全称 | E1: 报表月份供应商 | F1: 运输单位 | G1: 车数 | H1: 重量 | I1: 发热量 | J1: 运费单价 | K1: 运费 | L1: 到厂价格
A2: 1 | B2: 2024-01 | C2: 大同煤矿集团北辛窑煤业有限公司（1-1火车） | D2: 大同煤矿集团北辛窑煤业有限公司 | E2: 2024-01-大同煤矿集团北辛窑煤业有限公司 | F2: 晋能快成物流科技有限公司 | G2: 1403 | H2: 26101.84 | I2: 3501 | J2: =VLOOKUP(D2,运费!B:C,2,0) -> 147.1 | K2: =H2*J2 -> 3839580.7 | L2: {=(_xlfn.IFS(I2>=4300,570/5500*I2,I2>=3800,0.0806*I2,I2>=3300,0.0706*I2,I2>=2500,0.0676*I2,TRUE,0.02*I2)+10)*H2} -> 6712625.9 | M2: =3501*0.0676*H2 -> 6177459.8
A3: 2 | B3: 2024-01 | C3: 大同煤矿集团有限公司程家沟煤矿（1-1火车宝特） | D3: 大同煤矿集团有限公司程家沟煤矿 | E3: 2024-01-大同煤矿集团有限公司程家沟煤矿 | F3: 晋能快成物流科技有限公司 | G3: 500 | H3: 14377.61 | I3: 3311 | J3: =VLOOKUP(D3,运费!B:C,2,0) -> 192.75 | K3: =H3*J3 -> 2771284.3 | L3: {=(_xlfn.IFS(I3>=4300,570/5500*I3,I3>=3800,0.0806*I3,I3>=3300,0.0706*I3,I3>=2500,0.0676*I3,TRUE,0.02*I3)+10)*H3} -> 3504637.3
A4: 3 | B4: 2024-01 | C4: 河南农投供应链管理有限公司（1-1） | D4: 河南农投供应链管理有限公司 | E4: 2024-01-河南农投供应链管理有限公司 | F4: 晋能快成物流科技有限公司 | G4: 179 | H4: 3339.04 | I4: 4481 | J4: =VLOOKUP(D4,运费!B:C,2,0) -> 21.8 | K4: =H4*J4 -> 72791.072 | L4: {=(_xlfn.IFS(I4>=4300,570/5500*I4,I4>=3800,0.0806*I4,I4>=3300,0.0706*I4,I4>=2500,0.0676*I4,TRUE,0.02*I4)+10)*H4} -> 1584022.4
A5: 4 | B5: 2024-01 | C5: 河南农投供应链管理有限公司（12-2增量） | D5: 河南农投供应链管理有限公司 | E5: 2024-01-河南农投供应链管理有限公司 | F5: 晋能快成物流科技有限公司 | G5: 262 | H5: 4852.58 | I5: 4481 | J5: =VLOOKUP(D5,运费!B:C,2,0) -> 21.8 | K5: =H5*J5 -> 105786.24 | L5: {=(_xlfn.IFS(I5>=4300,570/5500*I5,I5>=3800,0.0806*I5,I5>=3300,0.0706*I5,I5>=2500,0.0676*I5,TRUE,0.02*I5)+10)*H5} -> 2302037.5 | M5: =I5*(570/5500+10)*H5 -> 2.1969762e+08
A6: 5 | B6: 2024-01 | C6: 洪洞阳光能源有限公司（12-1） | D6: 洪洞阳光能源有限公司 | E6: 2024-01-洪洞阳光能源有限公司 | F6: 晋能快成物流科技有限公司 | G6: 235 | H6: 4284.12 | I6: 3960 | J6: =VLOOKUP(D6,运费!B:C,2,0) -> 10.355 | K6: =H6*J6 -> 44362.063 | L6: {=(_xlfn.IFS(I6>=4300,570/5500*I6,I6>=3800,0.0806*I6,I6>=3300,0.0706*I6,I6>=2500,0.0676*I6,TRUE,0.02*I6)+10)*H6} -> 1410229.5
A7: 6 | B7: 2024-01 | C7: 侯马鼎坤源能源有限公司（1-1） | D7: 侯马鼎坤源能源有限公司 | E7: 2024-01-侯马鼎坤源能源有限公司 | F7: 晋能快成物流科技有限公司 | G7: 109 | H7: 3296 | I7: 4176 | J7: =VLOOKUP(D7,运费!B:C,2,0) -> 33.79 | K7: =H7*J7 -> 111371.84 | L7: {=(_xlfn.IFS(I7>=4300,570/5500*I7,I7>=3800,0.0806*I7,I7>=3300,0.0706*I7,I7>=2500,0.0676*I7,TRUE,0.02*I7)+10)*H7} -> 1142346.1 | M7: =SUMPRODUCT(H2:H216,I2:I216)/SUM(H2:H216) -> 3882.4024
A8: 7 | B8: 2024-01 | C8: 晋能控股集团盛泰煤业有限公司（1-1） | D8: 晋能控股集团盛泰煤业有限公司 | E8: 2024-01-晋能控股集团盛泰煤业有限公司 | F8: 晋能快成物流科技有限公司 | G8: 612 | H8: 19855.3 | I8: 4288 | J8: =VLOOKUP(D8,运费!B:C,2,0) -> 104.5 | K8: =H8*J8 -> 2074878.8 | L8: {=(_xlfn.IFS(I8>=4300,570/5500*I8,I8>=3800,0.0806*I8,I8>=3300,0.0706*I8,I8>=2500,0.0676*I8,TRUE,0.02*I8)+10)*H8} -> 7060798.8
A9: 8 | B9: 2024-01 | C9: 晋能控股煤业集团沁水胡底煤业有限公司（1-1） | D9: 晋能控股煤业集团沁水胡底煤业有限公司 | E9: 2024-01-晋能控股煤业集团沁水胡底煤业有限公司 | F9: 晋能快成物流科技有限公司 | G9: 182 | H9: 5754 | I9: 4511 | J9: =VLOOKUP(D9,运费!B:C,2,0) -> 78 | K9: =H9*J9 -> 448812 | L9: {=(_xlfn.IFS(I9>=4300,570/5500*I9,I9>=3800,0.0806*I9,I9>=3300,0.0706*I9,I9>=2500,0.0676*I9,TRUE,0.02*I9)+10)*H9} -> 2747555.9
A10: 9 | B10: 2024-01 | C10: 晋能控股煤业集团翼城华泓煤业有限公司（1-1） | D10: 晋能控股煤业集团翼城华泓煤业有限公司 | E10: 2024-01-晋能控股煤业集团翼城华泓煤业有限公司 | F10: 晋能快成物流科技有限公司 | G10: 879 | H10: 28078.13 | I10: 4388 | J10: =VLOOKUP(D10,运费!B:C,2,0) -> 58 | K10: =H10*J10 -> 1628531.5 | L10: {=(_xlfn.IFS(I10>=4300,570/5500*I10,I10>=3800,0.0806*I10,I10>=3300,0.0706*I10,I10>=2500,0.0676*I10,TRUE,0.02*I10)+10)*H10} -> 13049490
A11: 10 | B11: 2024-01 | C11: 临汾市侯马经济开发区鑫鑫商贸有限公司（1-1） | D11: 临汾市侯马经济开发区鑫鑫商贸有限公司 | E11: 2024-01-临汾市侯马经济开发区鑫鑫商贸有限公司 | F11: 晋能快成物流科技有限公司 | G11: 325 | H11: 5873.36 | I11: 4448 | J11: =VLOOKUP(D11,运费!B:C,2,0) -> 10.355 | K11: =H11*J11 -> 60818.643 | L11: {=(_xlfn.IFS(I11>=4300,570/5500*I11,I11>=3800,0.0806*I11,I11>=3300,0.0706*I11,I11>=2500,0.0676*I11,TRUE,0.02*I11)+10)*H11} -> 2766203.1
A12: 11 | B12: 2024-01 | C12: 临汾市侯马经济开发区鑫鑫商贸有限公司（12-1） | D12: 临汾市侯马经济开发区鑫鑫商贸有限公司 | E12: 2024-01-临汾市侯马经济开发区鑫鑫商贸有限公司 | F12: 晋能快成物流科技有限公司 | G12: 118 | H12: 2144.96 | I12: 4448 | J12: =VLOOKUP(D12,运费!B:C,2,0) -> 10.355 | K12: =H12*J12 -> 22211.061 | L12: {=(_xlfn.IFS(I12>=4300,570/5500*I12,I12>=3800,0.0806*I12,I12>=3300,0.0706*I12,I12>=2500,0.0676*I12,TRUE,0.02*I12)+10)*H12} -> 1010221.6
A13: 12 | B13: 2024-01 | C13: 山西芳瑞芳菲商贸有限公司(12-2增量) | D13: 山西芳瑞芳菲商贸有限公司 | E13: 2024-01-山西芳瑞芳菲商贸有限公司 | F13: 晋能快成物流科技有限公司 | G13: 132 | H13: 2411.82 | I13: 4032 | J13: =VLOOKUP(D13,运费!B:C,2,0) -> 10.355 | K13: =H13*J13 -> 24974.396 | L13: {=(_xlfn.IFS(I13>=4300,570/5500*I13,I13>=3800,0.0806*I13,I13>=3300,0.0706*I13,I13>=2500,0.0676*I13,TRUE,0.02*I13)+10)*H13} -> 807909.53
A14: 13 | B14: 2024-01 | C14: 山西汾河焦煤股份有限公司三交河煤矿（1-1） | D14: 山西汾河焦煤股份有限公司三交河煤矿 | E14: 2024-01-山西汾河焦煤股份有限公司三交河煤矿 | F14: 山西焦煤物流有限责任公司 | G14: 156 | H14: 4941.26 | I14: 4056 | J14: =VLOOKUP(D14,运费!B:C,2,0) -> 117 | K14: =H14*J14 -> 578127.42 | L14: {=(_xlfn.IFS(I14>=4300,570/5500*I14,I14>=3800,0.0806*I14,I14>=3300,0.0706*I14,I14>=2500,0.0676*I14,TRUE,0.02*I14)+10)*H14} -> 1664777.7
A15: 14 | B15: 2024-01 | C15: 山西焦煤汾西矿业昊锦塬煤业(1-1) | D15: 山西焦煤汾西矿业昊锦塬煤业 | E15: 2024-01-山西焦煤汾西矿业昊锦塬煤业 | F15: 山西焦煤物流有限责任公司 | G15: 19 | H15: 610.06 | I15: 3866 | J15: =VLOOKUP(D15,运费!B:C,2,0) -> 81 | K15: =H15*J15 -> 49414.86 | L15: {=(_xlfn.IFS(I15>=4300,570/5500*I15,I15>=3800,0.0806*I15,I15>=3300,0.0706*I15,I15>=2500,0.0676*I15,TRUE,0.02*I15)+10)*H15} -> 196195.05
A16: 15 | B16: 2024-01 | C16: 山西焦煤集团辛置矿（1-1） | D16: 山西焦煤集团辛置矿 | E16: 2024-01-山西焦煤集团辛置矿 | F16: 山西焦煤物流有限责任公司 | G16: 92 | H16: 2957.5 | I16: 3355 | J16: =VLOOKUP(D16,运费!B:C,2,0) -> 79 | K16: =H16*J16 -> 233642.5 | L16: {=(_xlfn.IFS(I16>=4300,570/5500*I16,I16>=3800,0.0806*I16,I16>=3300,0.0706*I16,I16>=2500,0.0676*I16,TRUE,0.02*I16)+10)*H16} -> 730097.32
A17: 16 | B17: 2024-01 | C17: 山西焦煤集团昊兴塬煤业（1-1） | D17: 山西焦煤集团昊兴塬煤业 | E17: 2024-01-山西焦煤集团昊兴塬煤业 | F17: 山西焦煤物流有限责任公司 | G17: 77 | H17: 2423.62 | I17: 3618 | J17: =VLOOKUP(D17,运费!B:C,2,0) -> 85 | K17: =H17*J17 -> 206007.7 | L17: {=(_xlfn.IFS(I17>=4300,570/5500*I17,I17>=3800,0.0806*I17,I17>=3300,0.0706*I17,I17>=2500,0.0676*I17,TRUE,0.02*I17)+10)*H17} -> 643303.4
A18: 17 | B18: 2024-01 | C18: 山西晋煤集团晋圣亿欣煤业有限公司（1-1） | D18: 山西晋煤集团晋圣亿欣煤业有限公司 | E18: 2024-01-山西晋煤集团晋圣亿欣煤业有限公司 | F18: 晋能快成物流科技有限公司 | G18: 398 | H18: 12357.18 | I18: 3587 | J18: =VLOOKUP(D18,运费!B:C,2,0) -> 67 | K18: =H18*J18 -> 827931.06 | L18: {=(_xlfn.IFS(I18>=4300,570/5500*I18,I18>=3800,0.0806*I18,I18>=3300,0.0706*I18,I18>=2500,0.0676*I18,TRUE,0.02*I18)+10)*H18} -> 3252931.2
A19: 18 | B19: 2024-01 | C19: 山西骏盛通能源有限公司（1-1） | D19: 山西骏盛通能源有限公司 | E19: 2024-01-山西骏盛通能源有限公司 | F19: 晋能快成物流科技有限公司 | G19: 426 | H19: 7751.66 | I19: 4296 | J19: =VLOOKUP(D19,运费!B:C,2,0) -> 10.355 | K19: =H19*J19 -> 80268.439 | L19: {=(_xlfn.IFS(I19>=4300,570/5500*I19,I19>=3800,0.0806*I19,I19>=3300,0.0706*I19,I19>=2500,0.0676*I19,TRUE,0.02*I19)+10)*H19} -> 2761587.8
... A42: 8 | B42: 2024-02 | C42: 山西汾河焦煤股份有限公司三交河煤矿（2-1） | D42: 山西汾河焦煤股份有限公司三交河煤矿 | E42: 2024-02-山西汾河焦煤股份有限公司三交河煤矿 | F42: 山西焦煤物流有限责任公司 | G42: 237 | H42: 7537.78 | I42: 4102 | J42: =VLOOKUP(D42,运费!B:C,2,0) -> 117 | K42: =H42*J42 -> 881920.26 | L42: {=(_xlfn.IFS(I42>=4300,570/5500*I42,I42>=3800,0.0806*I42,I42>=3300,0.0706*I42,I42>=2500,0.0676*I42,TRUE,0.02*I42)+10)*H42} -> 2567527.7
A43: 9 | B43: 2024-02 | C43: 山西焦煤汾西矿业昊锦塬煤业(2-1) | D43: 山西焦煤汾西矿业昊锦塬煤业 | E43: 2024-02-山西焦煤汾西矿业昊锦塬煤业 | F43: 山西焦煤物流有限责任公司 | G43: 14 | H43: 441.28 | J43: =VLOOKUP(D43,运费!B:C,2,0) -> 81 | K43: =H43*J43 -> 35743.68 | L43: {=(_xlfn.IFS(I43>=4300,570/5500*I43,I43>=3800,0.0806*I43,I43>=3300,0.0706*I43,I43>=2500,0.0676*I43,TRUE,0.02*I43)+10)*H43} -> 4412.8
A44: 10 | B44: 2024-02 | C44: 山西焦煤集团辛置矿（2-1） | D44: 山西焦煤集团辛置矿 | E44: 2024-02-山西焦煤集团辛置矿 | F44: 山西焦煤物流有限责任公司 | G44: 6 | H44: 193.4 | I44: 4146 | J44: =VLOOKUP(D44,运费!B:C,2,0) -> 79 | K44: =H44*J44 -> 15278.6 | L44: {=(_xlfn.IFS(I44>=4300,570/5500*I44,I44>=3800,0.0806*I44,I44>=3300,0.0706*I44,I44>=2500,0.0676*I44,TRUE,0.02*I44)+10)*H44} -> 66562.014
A45: 11 | B45: 2024-02 | C45: 山西骏盛通能源有限公司（1-1） | D45: 山西骏盛通能源有限公司 | E45: 2024-02-山西骏盛通能源有限公司 | F45: 晋能快成物流科技有限公司 | G45: 376 | H45: 6697.86 | I45: 4105 | J45: =VLOOKUP(D45,运费!B:C,2,0) -> 10.355 | K45: =H45*J45 -> 69356.34 | L45: {=(_xlfn.IFS(I45>=4300,570/5500*I45,I45>=3800,0.0806*I45,I45>=3300,0.0706*I45,I45>=2500,0.0676*I45,TRUE,0.02*I45)+10)*H45} -> 2283052.7
A46: 12 | B46: 2024-02 | C46: 山西煤炭运销集团盖州煤业有限公司（2-1） | D46: 山西煤炭运销集团盖州煤业有限公司 | E46: 2024-02-山西煤炭运销集团盖州煤业有限公司 | F46: 晋能快成物流科技有限公司 | G46: 77 | H46: 2505.84 | I46: 3959 | J46: =VLOOKUP(D46,运费!B:C,2,0) -> 101.5 | K46: =H46*J46 -> 254342.76 | L46: {=(_xlfn.IFS(I46>=4300,570/5500*I46,I46>=3800,0.0806*I46,I46>=3300,0.0706*I46,I46>=2500,0.0676*I46,TRUE,0.02*I46)+10)*H46} -> 824660.42
A47: 13 | B47: 2024-02 | C47: 山西煤炭运销集团神农煤业有限公司（2-1） | D47: 山西煤炭运销集团神农煤业有限公司 | E47: 2024-02-山西煤炭运销集团神农煤业有限公司 | F47: 晋能快成物流科技有限公司 | G47: 13 | H47: 421.96 | J47: =VLOOKUP(D47,运费!B:C,2,0) -> 105 | K47: =H47*J47 -> 44305.8 | L47: {=(_xlfn.IFS(I47>=4300,570/5500*I47,I47>=3800,0.0806*I47,I47>=3300,0.0706*I47,I47>=2500,0.0676*I47,TRUE,0.02*I47)+10)*H47} -> 4219.6
A48: 14 | B48: 2024-02 | C48: 山西煤炭运销集团四明山煤业有限公司（2-1） | D48: 山西煤炭运销集团四明山煤业有限公司 | E48: 2024-02-山西煤炭运销集团四明山煤业有限公司 | F48: 晋能快成物流科技有限公司 | G48: 91 | H48: 2963.04 | I48: 4139 | J48: =VLOOKUP(D48,运费!B:C,2,0) -> 104.5 | K48: =H48*J48 -> 309637.68 | L48: {=(_xlfn.IFS(I48>=4300,570/5500*I48,I48>=3800,0.0806*I48,I48>=3300,0.0706*I48,I48>=2500,0.0676*I48,TRUE,0.02*I48)+10)*H48} -> 1018110.6
A49: 15 | B49: 2024-02 | C49: 山西统配煤炭物流有限公司（1-1） | D49: 山西统配煤炭物流有限公司 | E49: 2024-02-山西统配煤炭物流有限公司 | F49: 晋能快成物流科技有限公司 | G49: 292 | H49: 5396.88 | I49: 4283 | J49: =VLOOKUP(D49,运费!B:C,2,0) -> 21.8 | K49: =H49*J49 -> 117651.98 | L49: {=(_xlfn.IFS(I49>=4300,570/5500*I49,I49>=3800,0.0806*I49,I49>=3300,0.0706*I49,I49>=2500,0.0676*I49,TRUE,0.02*I49)+10)*H49} -> 1917024.7
A50: 16 | B50: 2024-02 | C50: 山西鑫健商贸有限公司（1-1） | D50: 山西鑫健商贸有限公司 | E50: 2024-02-山西鑫健商贸有限公司 | F50: 晋能快成物流科技有限公司 | G50: 900 | H50: 16706.1 | I50: 4153 | J50: =VLOOKUP(D50,运费!B:C,2,0) -> 21.8 | K50: =H50*J50 -> 364192.98 | L50: {=(_xlfn.IFS(I50>=4300,570/5500*I50,I50>=3800,0.0806*I50,I50>=3300,0.0706*I50,I50>=2500,0.0676*I50,TRUE,0.02*I50)+10)*H50} -> 5759123.9
A51: 17 | B51: 2024-02 | C51: 太原煤气化股份有限公司炉峪口煤矿（1-1宝特） | D51: 太原煤气化股份有限公司炉峪口煤矿 | E51: 2024-02-太原煤气化股份有限公司炉峪口煤矿 | F51: 晋能快成物流科技有限公司 | G51: 124 | H51: 3591.06 | I51: 3064 | J51: =VLOOKUP(D51,运费!B:C,2,0) -> 116.8 | K51: =H51*J51 -> 419435.81 | L51: {=(_xlfn.IFS(I51>=4300,570/5500*I51,I51>=3800,0.0806*I51,I51>=3300,0.0706*I51,I51>=2500,0.0676*I51,TRUE,0.02*I51)+10)*H51} -> 779713.93
A52: 18 | B52: 2024-02 | C52: 太原煤气化股份有限公司炉峪口煤矿（2-1宝特） | D52: 太原煤气化股份有限公司炉峪口煤矿 | E52: 2024-02-太原煤气化股份有限公司炉峪口煤矿 | F52: 晋能快成物流科技有限公司 | G52: 169 | H52: 3520.84 | I52: 3064 | J52: =VLOOKUP(D52,运费!B:C,2,0) -> 116.8 | K52: =H52*J52 -> 411234.11 | L52: {=(_xlfn.IFS(I52>=4300,570/5500*I52,I52>=3800,0.0806*I52,I52>=3300,0.0706*I52,I52>=2500,0.0676*I52,TRUE,0.02*I52)+10)*H52} -> 764467.31
A53: 19 | B53: 2024-02 | C53: 太原煤气化龙泉能源（1-1火车） | D53: 太原煤气化龙泉能源 | E53: 2024-02-太原煤气化龙泉能源 | F53: 晋能快成物流科技有限公司 | G53: 380 | H53: 6978.76 | I53: 4863 | J53: =VLOOKUP(D53,运费!B:C,2,0) -> 108.51 | K53: =H53*J53 -> 757265.25 | L53: {=(_xlfn.IFS(I53>=4300,570/5500*I53,I53>=3800,0.0806*I53,I53>=3300,0.0706*I53,I53>=2500,0.0676*I53,TRUE,0.02*I53)+10)*H53} -> 3586968.4
A54: 20 | B54: 2024-02 | C54: 太原煤气化龙泉能源（2-1火车） | D54: 太原煤气化龙泉能源 | E54: 2024-02-太原煤气化龙泉能源 | F54: 晋能快成物流科技有限公司 | G54: 745 | H54: 13746.38 | I54: 4863 | J54: =VLOOKUP(D54,运费!B:C,2,0) -> 108.51 | K54: =H54*J54 -> 1491619.7 | L54: {=(_xlfn.IFS(I54>=4300,570/5500*I54,I54>=3800,0.0806*I54,I54>=3300,0.0706*I54,I54>=2500,0.0676*I54,TRUE,0.02*I54)+10)*H54} -> 7065414.4
A55: 21 | B55: 2024-02 | C55: 襄汾县浩群煤业有限公司（1-1） | D55: 襄汾县浩群煤业有限公司 | E55: 2024-02-襄汾县浩群煤业有限公司 | F55: 晋能快成物流科技有限公司 | G55: 32 | H55: 723.02 | I55: 4374 | J55: =VLOOKUP(D55,运费!B:C,2,0) -> 33.79 | K55: =H55*J55 -> 24430.846 | L55: {=(_xlfn.IFS(I55>=4300,570/5500*I55,I55>=3800,0.0806*I55,I55>=3300,0.0706*I55,I55>=2500,0.0676*I55,TRUE,0.02*I55)+10)*H55} -> 334979.11
A56: 22 | B56: 2024-02 | C56: 阳泉煤业集团翼城山凹煤业有限公司（2-1） | D56: 阳泉煤业集团翼城山凹煤业有限公司 | E56: 2024-02-阳泉煤业集团翼城山凹煤业有限公司 | F56: 晋能快成物流科技有限公司 | G56: 92 | H56: 2937.34 | I56: 4579 | J56: =VLOOKUP(D56,运费!B:C,2,0) -> 60.5 | K56: =H56*J56 -> 177709.07 | L56: {=(_xlfn.IFS(I56>=4300,570/5500*I56,I56>=3800,0.0806*I56,I56>=3300,0.0706*I56,I56>=2500,0.0676*I56,TRUE,0.02*I56)+10)*H56} -> 1423290.8
A57: 1 | B57: 2024-03 | C57: 大同煤矿集团北辛窑煤业有限公司（2-1火车） | D57: 大同煤矿集团北辛窑煤业有限公司 | E57: 2024-03-大同煤矿集团北辛窑煤业有限公司 | F57: 晋能快成物流科技有限公司 | G57: 1086 | H57: 20164.9 | I57: 3409 | J57: =VLOOKUP(D57,运费!B:C,2,0) -> 147.1 | K57: =H57*J57 -> 2966256.8 | L57: {=(_xlfn.IFS(I57>=4300,570/5500*I57,I57>=3800,0.0806*I57,I57>=3300,0.0706*I57,I57>=2500,0.0676*I57,TRUE,0.02*I57)+10)*H57} -> 5054844.4
A58: 2 | B58: 2024-03 | C58: 大同煤矿集团北辛窑煤业有限公司（3-1火车） | D58: 大同煤矿集团北辛窑煤业有限公司 | E58: 2024-03-大同煤矿集团北辛窑煤业有限公司 | F58: 晋能快成物流科技有限公司 | G58: 1393 | H58: 26168.38 | I58: 3409 | J58: =VLOOKUP(D58,运费!B:C,2,0) -> 147.1 | K58: =H58*J58 -> 3849368.7 | L58: {=(_xlfn.IFS(I58>=4300,570/5500*I58,I58>=3800,0.0806*I58,I58>=3300,0.0706*I58,I58>=2500,0.0676*I58,TRUE,0.02*I58)+10)*H58} -> 6559769.1
A59: 3 | B59: 2024-03 | C59: 晋能控股集团盛泰煤业有限公司（2-1） | D59: 晋能控股集团盛泰煤业有限公司 | E59: 2024-03-晋能控股集团盛泰煤业有限公司 | F59: 晋能快成物流科技有限公司 | G59: 16 | H59: 517.74 | I59: 3944 | J59: =VLOOKUP(D59,运费!B:C,2,0) -> 104.5 | K59: =H59*J59 -> 54103.83 | L59: {=(_xlfn.IFS(I59>=4300,570/5500*I59,I59>=3800,0.0806*I59,I59>=3300,0.0706*I59,I59>=2500,0.0676*I59,TRUE,0.02*I59)+10)*H59} -> 169759.9
... A78: 2 | B78: 2024-04 | C78: 晋能控股集团盛泰煤业有限公司（4-1） | D78: 晋能控股集团盛泰煤业有限公司 | E78: 2024-04-晋能控股集团盛泰煤业有限公司 | F78: 晋能快成物流科技有限公司 | G78: 179 | H78: 5858.72 | I78: 5138 | J78: =VLOOKUP(D78,运费!B:C,2,0) -> 104.5 | K78: =H78*J78 -> 612236.24 | L78: {=(_xlfn.IFS(I78>=4300,570/5500*I78,I78>=3800,0.0806*I78,I78>=3300,0.0706*I78,I78>=2500,0.0676*I78,TRUE,0.02*I78)+10)*H78} -> 3178259.7
A79: 3 | B79: 2024-04 | C79: 晋能控股煤业集团沁水胡底煤业有限公司（4-1） | D79: 晋能控股煤业集团沁水胡底煤业有限公司 | E79: 2024-04-晋能控股煤业集团沁水胡底煤业有限公司 | F79: 晋能快成物流科技有限公司 | G79: 46 | H79: 1437.8 | J79: =VLOOKUP(D79,运费!B:C,2,0) -> 78 | K79: =H79*J79 -> 112148.4 | L79: {=(_xlfn.IFS(I79>=4300,570/5500*I79,I79>=3800,0.0806*I79,I79>=3300,0.0706*I79,I79>=2500,0.0676*I79,TRUE,0.02*I79)+10)*H79} -> 14378
A80: 4 | B80: 2024-04 | C80: 晋能控股煤业集团翼城华泓煤业有限公司（4-1） | D80: 晋能控股煤业集团翼城华泓煤业有限公司 | E80: 2024-04-晋能控股煤业集团翼城华泓煤业有限公司 | F80: 晋能快成物流科技有限公司 | G80: 258 | H80: 8264.73 | I80: 3956 | J80: =VLOOKUP(D80,运费!B:C,2,0) -> 58 | K80: =H80*J80 -> 479354.34 | L80: {=(_xlfn.IFS(I80>=4300,570/5500*I80,I80>=3800,0.0806*I80,I80>=3300,0.0706*I80,I80>=2500,0.0676*I80,TRUE,0.02*I80)+10)*H80} -> 2717886.2
...

Sheet 运费
A1: 供应商 | B1: 供应商业称 | C1: 含税运费 | D1: 类别 | E1: 运输方式 | F1: 矿发单价 | G1: 忻州物流 | H1: 铁路运费 | I1: 上站装卸 | J1: 上站短倒 | K1: 下站装卸 | L1: 到厂快成单价
A2: 山凹 | B2: 阳泉煤业集团翼城山凹煤业有限公司 | C2: 60.5 | D2: 集团煤 | E2: 汽运 | L2: 60.5
A3: 华泓 | B3: 晋能控股煤业集团翼城华泓煤业有限公司 | C3: 58 | D3: 集团煤 | E3: 汽运 | L3: 58
A4: 炉峪口 | B4: 太原煤气化股份有限公司炉峪口煤矿 | C4: 116.8 | D4: 集团煤 | E4: 铁路 | H4: 80.3 | K4: 13 | L4: 23.5
A5: 龙泉 | B5: 太原煤气化龙泉能源 | C5: 108.51 | D5: 集团煤 | E5: 铁路 | H5: 72.01 | K5: 13 | L5: 23.5
A6: 华胜 | B6: 山西蒲县华胜煤业有限公司 | C6: 82 | D6: 集团煤 | E6: 汽运 | L6: 82
A7: 晋牛 | B7: 山西晋煤集团临汾晋牛煤矿投资有限责任公司 | C7: 108 | D7: 焦煤 | E7: 汽运
A8: 雪坪 | B8: 山西焦煤霍州煤电雪坪煤业有限公司 | C8: 70 | D8: 焦煤 | E8: 汽运
A9: 亿欣 | B9: 山西晋煤集团晋圣亿欣煤业有限公司 | C9: 67 | D9: 集团煤 | E9: 汽运 | L9: 67
A10: 昊兴塬 | B10: 山西焦煤集团昊兴塬煤业 | C10: 85 | D10: 焦煤 | E10: 汽运
A11: 金辛达 | B11: 山西焦煤集团金辛达煤业 | C11: 113 | D11: 焦煤 | E11: 汽运
A12: 程家沟 | B12: 大同煤矿集团有限公司程家沟煤矿 | C12: 192.75 | D12: 集团煤 | E12: 铁路 | H12: 90.25 | I12: 40 | J12: 26 | K12: 13 | L12: 23.5
A13: 同基 | C13: 206.06 | D13: 集团煤 | E13: 铁路 | H13: 89.56 | I13: 40 | J13: 40 | K13: 13 | L13: 23.5
A14: 北辛窑 | B14: 大同煤矿集团北辛窑煤业有限公司 | C14: 147.1 | D14: 集团煤 | E14: 铁路 | G14: 45.6 | H14: 65 | K14: 13 | L14: 23.5
A15: 四明山 | B15: 山西煤炭运销集团四明山煤业有限公司 | C15: 104.5 | D15: 集团煤 | E15: 汽运 | L15: 104.5
A16: 盖州 | B16: 山西煤炭运销集团盖州煤业有限公司 | C16: 101.5 | D16: 集团煤 | E16: 汽运 | L16: 101.5
A17: 胡底 | B17: 晋能控股煤业集团沁水胡底煤业有限公司 | C17: 78 | D17: 集团煤 | E17: 汽运 | L17: 78
A18: 昊锦塬 | B18: 山西焦煤汾西矿业昊锦塬煤业 | C18: 81 | D18: 焦煤 | E18: 汽运
A19: 盛泰 | B19: 晋能控股集团盛泰煤业有限公司 | C19: 104.5 | D19: 集团煤 | E19: 汽运 | L19: 104.5
A20: 三交河 | B20: 山西汾河焦煤股份有限公司三交河煤矿 | C20: 117 | D20: 焦煤 | E20: 汽运
A21: 神农 | B21: 山西煤炭运销集团神农煤业有限公司 | C21: 105 | D21: 集团煤 | E21: 汽运 | L21: 105
A22: 坪上 | B22: 晋能控股集团沁秀公司坪上煤业 | C22: 78 | D22: 集团煤 | E22: 汽运 | L22: 78
A23: 焦煤国际 | B23: 山西焦煤集团国际贸易有限责任公司 | C23: 68 | D23: 焦煤 | E23: 汽运
A24: 岳城 | B24: 山西晋煤集团沁秀煤业有限公司岳城煤矿 | C24: 81 | D24: 集团煤 | E24: 汽运 | L24: 81
A25: 襄汾浩群 | B25: 襄汾县浩群煤业有限公司 | C25: =31*1.09 -> 33.79 | D25: 市场煤 | E25: 汽运
A26: 搿悦能源 | B26: 山西搿悦能源科技有限公司 | C26: =20*1.09 -> 21.8 | D26: 市场煤 | E26: 汽运
A27: 鑫健商贸 | B27: 山西鑫健商贸有限公司 | C27: =20*1.09 -> 21.8 | D27: 市场煤 | E27: 汽运
A28: 洪洞阳光 | B28: 洪洞阳光能源有限公司 | C28: =9.5*1.09 -> 10.355 | D28: 市场煤 | E28: 汽运
A29: 芳瑞芳菲 | B29: 山西芳瑞芳菲商贸有限公司 | C29: =9.5*1.09 -> 10.355 | D29: 市场煤 | E29: 汽运
A30: 鼎坤源 | B30: 侯马鼎坤源能源有限公司 | C30: =31*1.09 -> 33.79 | D30: 市场煤 | E30: 汽运
A31: 陆港现代 | B31: 山西陆港现代物流发展有限公司 | C31: =20*1.09 -> 21.8 | D31: 市场煤 | E31: 汽运
A32: 河南农投 | B32: 河南农投供应链管理有限公司 | C32: =20*1.09 -> 21.8 | D32: 市场煤 | E32: 汽运
A33: 山西统配 | B33: 山西统配煤炭物流有限公司 | C33: =20*1.09 -> 21.8 | D33: 市场煤 | E33: 汽运
A34: 鑫鑫商贸 | B34: 临汾市侯马经济开发区鑫鑫商贸有限公司 | C34: =9.5*1.09 -> 10.355 | D34: 市场煤 | E34: 汽运
A35: 骏盛通 | B35: 山西骏盛通能源有限公司 | C35: =9.5*1.09 -> 10.355 | D35: 市场煤 | E35: 汽运
A36: 太行云商 | B36: 山西太行云商科技有限公司 | C36: =9.5*1.09 -> 10.355 | D36: 市场煤 | E36: 汽运
A37: 小峪 | B37: 大同煤矿集团朔煤小峪煤业有限公司 | C37: 143.92 | D37: 集团煤 | E37: 铁路 | H37: 107.42 | K37: 13 | L37: 23.5
A38: 莲盛 | B38: 山西煤炭运销集团莲盛有限公司 | C38: 175.5 | D38: 集团煤 | E38: 铁路 | F38: 36 | G38: 38 | H38: 65 | K38: 13 | L38: 23.5
A39: 野川 | B39: 山西煤炭运销集团野川有限公司 | C39: 114.09 | D39: 集团煤 | E39: 汽运 | L39: 114.09
A40: 辛置 | B40: 山西焦煤集团辛置矿 | C40: 79 | D40: 焦煤 | E40: 汽运
...
